Workbook

Sheet Cu_1stPhase
A1: Freq | B1: Magnitude | C1: Phase | D1: Time (date) | E1: Magnitude - R | F1: Bread Magnitude - Baseline | G1: Time[s] | H1: ln with baseline | I1: ln(Magnitude)
A2: 1000 | B2: 2105.165 | C2: -18.278601 | D2: Tue Nov 23 13:36:44 2021 | E2: =B2-$P$3 -> 627.16504 | F2: =E2-$R$3 -> #VALUE! | G2: 0 | H2: =LN(F2) -> #VALUE! | I2: =LN(B2) -> 7.6521491 | L2: All values | M2: 0-500 s | P2: Serie Resistor | R2: Baseline
A3: 1000 | B3: 2099.2402 | C3: -18.210516 | D3: Tue Nov 23 13:36:55 2021 | E3: =B3-$P$3 -> 621.24023 | F3: =E3-$R$3 -> #VALUE! | G3: 10 | H3: =LN(F3) -> #VALUE! | I3: =LN(B3) -> 7.6493308 | K3: Tau: | L3: =1/(0.00008) -> 12500 | M3: =1/(0.00009) -> 11111.111 | N3: s | P3: 1478 | R3: -
A4: 1000 | B4: 2102.4377 | C4: -18.134974 | D4: Tue Nov 23 13:37:05 2021 | E4: =B4-$P$3 -> 624.43774 | F4: =E4-$R$3 -> #VALUE! | G4: 20 | H4: =LN(F4) -> #VALUE! | I4: =LN(B4) -> 7.6508528 | L4: =L3/60 -> 208.33333 | M4: =M3/60 -> 185.18519 | N4: min
A5: 1000 | B5: 2097.8953 | C5: -18.019749 | D5: Tue Nov 23 13:37:15 2021 | E5: =B5-$P$3 -> 619.89526 | F5: =E5-$R$3 -> #VALUE! | G5: 30 | H5: =LN(F5) -> #VALUE! | I5: =LN(B5) -> 7.6486899 | L5: =L4/60 -> 3.4722222 | M5: =M4/60 -> 3.0864198 | N5: h
A6: 1000 | B6: 2093.26 | C6: -17.916996 | D6: Tue Nov 23 13:37:25 2021 | E6: =B6-$P$3 -> 615.26001 | F6: =E6-$R$3 -> #VALUE! | G6: 40 | H6: =LN(F6) -> #VALUE! | I6: =LN(B6) -> 7.6464779
A7: 1000 | B7: 2090.1982 | C7: -17.894073 | D7: Tue Nov 23 13:37:35 2021 | E7: =B7-$P$3 -> 612.19824 | F7: =E7-$R$3 -> #VALUE! | G7: 50 | H7: =LN(F7) -> #VALUE! | I7: =LN(B7) -> 7.6450142
A8: 1000 | B8: 2085.0476 | C8: -17.732225 | D8: Tue Nov 23 13:37:45 2021 | E8: =B8-$P$3 -> 607.04761 | F8: =E8-$R$3 -> #VALUE! | G8: 60 | H8: =LN(F8) -> #VALUE! | I8: =LN(B8) -> 7.642547
A9: 1000 | B9: 2079.8745 | C9: -17.633829 | D9: Tue Nov 23 13:37:55 2021 | E9: =B9-$P$3 -> 601.87451 | F9: =E9-$R$3 -> #VALUE! | G9: 70 | H9: =LN(F9) -> #VALUE! | I9: =LN(B9) -> 7.6400628
A10: 1000 | B10: 2077.3293 | C10: -17.576826 | D10: Tue Nov 23 13:38:05 2021 | E10: =B10-$P$3 -> 599.32935 | F10: =E10-$R$3 -> #VALUE! | G10: 80 | H10: =LN(F10) -> #VALUE! | I10: =LN(B10) -> 7.6388384
A11: 1000 | B11: 2074.0452 | C11: -17.520544 | D11: Tue Nov 23 13:38:15 2021 | E11: =B11-$P$3 -> 596.04517 | F11: =E11-$R$3 -> #VALUE! | G11: 90 | H11: =LN(F11) -> #VALUE! | I11: =LN(B11) -> 7.6372562
A12: 1000 | B12: 2072.7334 | C12: -17.51355 | D12: Tue Nov 23 13:38:25 2021 | E12: =B12-$P$3 -> 594.7334 | F12: =E12-$R$3 -> #VALUE! | G12: 100 | H12: =LN(F12) -> #VALUE! | I12: =LN(B12) -> 7.6366235
A13: 1000 | B13: 2069.3467 | C13: -17.410934 | D13: Tue Nov 23 13:38:36 2021 | E13: =B13-$P$3 -> 591.34668 | F13: =E13-$R$3 -> #VALUE! | G13: 110 | H13: =LN(F13) -> #VALUE! | I13: =LN(B13) -> 7.6349882
A14: 1000 | B14: 2064.1428 | C14: -17.214935 | D14: Tue Nov 23 13:38:45 2021 | E14: =B14-$P$3 -> 586.14282 | F14: =E14-$R$3 -> #VALUE! | G14: 120 | H14: =LN(F14) -> #VALUE! | I14: =LN(B14) -> 7.6324703
A15: 1000 | B15: 2060.5356 | C15: -17.088903 | D15: Tue Nov 23 13:38:55 2021 | E15: =B15-$P$3 -> 582.53564 | F15: =E15-$R$3 -> #VALUE! | G15: 130 | H15: =LN(F15) -> #VALUE! | I15: =LN(B15) -> 7.6307212
A16: 1000 | B16: 2056.8342 | C16: -16.934036 | D16: Tue Nov 23 13:39:05 2021 | E16: =B16-$P$3 -> 578.83423 | F16: =E16-$R$3 -> #VALUE! | G16: 140 | H16: =LN(F16) -> #VALUE! | I16: =LN(B16) -> 7.6289233
A17: 1000 | B17: 2053.3652 | C17: -16.8256 | D17: Tue Nov 23 13:39:15 2021 | E17: =B17-$P$3 -> 575.36523 | F17: =E17-$R$3 -> #VALUE! | G17: 150 | H17: =LN(F17) -> #VALUE! | I17: =LN(B17) -> 7.6272353
... A119: 1000 | B119: 1905.8677 | C119: -11.332351 | D119: Tue Nov 23 13:56:17 2021 | E119: =B119-$P$3 -> 427.86768 | F119: =E119-$R$3 -> #VALUE! | G119: 1170 | H119: =LN(F119) -> #VALUE! | I119: =LN(B119) -> 7.5526927

Sheet PANI_1stPhase
A1: Freq | B1: Magnitude | C1: Phase | D1: Time (date) | E1: Magnitude - R | F1: Bread Magnitude - Baseline | G1: Time[s] | H1: ln with baseline | I1: ln(Magnitude)
A2: 1000 | B2: 1956.8157 | C2: -11.351593 | D2: Tue Nov 23 13:35:01 2021 | E2: =B2-$P$3 -> 472.81567 | F2: =E2-$R$3 -> 159.33277 | G2: 0 | H2: =LN(F2) -> 5.0709949 | I2: =LN(B2) -> 7.5790738 | L2: All values | M2: 0-1000 s | P2: Serie Resistor | R2: Baseline
A3: 1000 | B3: 1918.7635 | C3: -10.750139 | D3: Tue Nov 23 13:35:11 2021 | E3: =B3-$P$3 -> 434.76355 | F3: =E3-$R$3 -> 121.28065 | G3: 10 | H3: =LN(F3) -> 4.7981073 | I3: =LN(B3) -> 7.5594363 | K3: Tau: | L3: =1/(0.00003) -> 33333.333 | M3: =1/(0.00004) -> 25000 | N3: s | P3: 1484 | R3: 313.4829
A4: 1000 | B4: 1898.6049 | C4: -10.275168 | D4: Tue Nov 23 13:35:21 2021 | E4: =B4-$P$3 -> 414.60486 | F4: =E4-$R$3 -> 101.12196 | G4: 20 | H4: =LN(F4) -> 4.6163273 | I4: =LN(B4) -> 7.5488746 | L4: =L3/60 -> 555.55556 | M4: =M3/60 -> 416.66667 | N4: min
A5: 1000 | B5: 1884.7805 | C5: -9.877228 | D5: Tue Nov 23 13:35:31 2021 | E5: =B5-$P$3 -> 400.78052 | F5: =E5-$R$3 -> 87.297618 | G5: 30 | H5: =LN(F5) -> 4.4693232 | I5: =LN(B5) -> 7.5415667 | L5: =L4/60 -> 9.2592593 | M5: =M4/60 -> 6.9444444 | N5: h
A6: 1000 | B6: 1875.8574 | C6: -9.648021 | D6: Tue Nov 23 13:35:41 2021 | E6: =B6-$P$3 -> 391.85742 | F6: =E6-$R$3 -> 78.374522 | G6: 40 | H6: =LN(F6) -> 4.3614989 | I6: =LN(B6) -> 7.5368211
A7: 1000 | B7: 1869.0836 | C7: -9.454494 | D7: Tue Nov 23 13:35:51 2021 | E7: =B7-$P$3 -> 385.08362 | F7: =E7-$R$3 -> 71.600718 | G7: 50 | H7: =LN(F7) -> 4.2711051 | I7: =LN(B7) -> 7.5332035
A8: 1000 | B8: 1863.626 | C8: -9.293615 | D8: Tue Nov 23 13:36:01 2021 | E8: =B8-$P$3 -> 379.62598 | F8: =E8-$R$3 -> 66.143077 | G8: 60 | H8: =LN(F8) -> 4.1918202 | I8: =LN(B8) -> 7.5302793
A9: 1000 | B9: 1859.1189 | C9: -9.22948 | D9: Tue Nov 23 13:36:04 2021 | E9: =B9-$P$3 -> 375.1189 | F9: =E9-$R$3 -> 61.635996 | G9: 70 | H9: =LN(F9) -> 4.1212461 | I9: =LN(B9) -> 7.5278579
A10: 1000 | B10: 1857.9279 | C10: -9.098941 | D10: Tue Nov 23 13:36:14 2021 | E10: =B10-$P$3 -> 373.92786 | F10: =E10-$R$3 -> 60.444956 | G10: 80 | H10: =LN(F10) -> 4.1017331 | I10: =LN(B10) -> 7.5272171
A11: 1000 | B11: 1854.7112 | C11: -9.012553 | D11: Tue Nov 23 13:36:24 2021 | E11: =B11-$P$3 -> 370.71118 | F11: =E11-$R$3 -> 57.228282 | G11: 90 | H11: =LN(F11) -> 4.0470482 | I11: =LN(B11) -> 7.5254843
A12: 1000 | B12: 1851.354 | C12: -8.889214 | D12: Tue Nov 23 13:36:34 2021 | E12: =B12-$P$3 -> 367.354 | F12: =E12-$R$3 -> 53.871104 | G12: 100 | H12: =LN(F12) -> 3.9865942 | I12: =LN(B12) -> 7.5236725
A13: 1000 | B13: 1849.7242 | C13: -8.839982 | D13: Tue Nov 23 13:36:44 2021 | E13: =B13-$P$3 -> 365.72424 | F13: =E13-$R$3 -> 52.241343 | G13: 110 | H13: =LN(F13) -> 3.9558742 | I13: =LN(B13) -> 7.5227918
A14: 1000 | B14: 1847.1276 | C14: -8.725849 | D14: Tue Nov 23 13:36:54 2021 | E14: =B14-$P$3 -> 363.12756 | F14: =E14-$R$3 -> 49.644663 | G14: 120 | H14: =LN(F14) -> 3.9048909 | I14: =LN(B14) -> 7.521387
A15: 1000 | B15: 1844.3237 | C15: -8.64677 | D15: Tue Nov 23 13:37:04 2021 | E15: =B15-$P$3 -> 360.32373 | F15: =E15-$R$3 -> 46.84083 | G15: 130 | H15: =LN(F15) -> 3.8467553 | I15: =LN(B15) -> 7.5198679
A16: 1000 | B16: 1841.7561 | C16: -8.596198 | D16: Tue Nov 23 13:37:14 2021 | E16: =B16-$P$3 -> 357.7561 | F16: =E16-$R$3 -> 44.273204 | G16: 140 | H16: =LN(F16) -> 3.7903796 | I16: =LN(B16) -> 7.5184748
A17: 1000 | B17: 1839.452 | C17: -8.533046 | D17: Tue Nov 23 13:37:24 2021 | E17: =B17-$P$3 -> 355.45203 | F17: =E17-$R$3 -> 41.969126 | G17: 150 | H17: =LN(F17) -> 3.7369343 | I17: =LN(B17) -> 7.517223
... A39: 1000 | B39: 1814.6549 | C39: -7.641584 | D39: Tue Nov 23 13:41:05 2021 | E39: =B39-$P$3 -> 330.65491 | F39: =E39-$R$3 -> 17.172007 | G39: 370 | H39: =LN(F39) -> 2.8432806 | I39: =LN(B39) -> 7.5036506
A40: 1000 | B40: 1813.1777 | C40: -7.59996 | D40: Tue Nov 23 13:41:15 2021 | E40: =B40-$P$3 -> 329.17773 | F40: =E40-$R$3 -> 15.694834 | G40: 380 | H40: =LN(F40) -> 2.7533316 | I40: =LN(B40) -> 7.5028362 | T40: -0.006
A41: 1000 | B41: 1812.8031 | C41: -7.572299 | D41: Tue Nov 23 13:41:25 2021 | E41: =B41-$P$3 -> 328.8031 | F41: =E41-$R$3 -> 15.320201 | G41: 390 | H41: =LN(F41) -> 2.7291723 | I41: =LN(B41) -> 7.5026296 | S41: Tau: | T41: =1/ABS(T40) -> 166.66667 | U41: s
A42: 1000 | B42: 1812.4696 | C42: -7.548584 | D42: Tue Nov 23 13:41:34 2021 | E42: =B42-$P$3 -> 328.4696 | F42: =E42-$R$3 -> 14.986704 | G42: 400 | H42: =LN(F42) -> 2.7071634 | I42: =LN(B42) -> 7.5024456 | T42: =T41/60 -> 2.7777778 | U42: min
A43: 1000 | B43: 1811.7451 | C43: -7.521372 | D43: Tue Nov 23 13:41:45 2021 | E43: =B43-$P$3 -> 327.74512 | F43: =E43-$R$3 -> 14.262217 | G43: 410 | H43: =LN(F43) -> 2.6576139 | I43: =LN(B43) -> 7.5020458 | T43: =T42/60 -> 0.046296296 | U43: h
A44: 1000 | B44: 1810.9095 | C44: -7.488136 | D44: Tue Nov 23 13:41:55 2021 | E44: =B44-$P$3 -> 326.90955 | F44: =E44-$R$3 -> 13.426646 | G44: 420 | H44: =LN(F44) -> 2.5972412 | I44: =LN(B44) -> 7.5015845
A45: 1000 | B45: 1810.1708 | C45: -7.44982 | D45: Tue Nov 23 13:42:05 2021 | E45: =B45-$P$3 -> 326.17078 | F45: =E45-$R$3 -> 12.687876 | G45: 430 | H45: =LN(F45) -> 2.5406469 | I45: =LN(B45) -> 7.5011765
A46: 1000 | B46: 1809.4647 | C46: -7.433659 | D46: Tue Nov 23 13:42:15 2021 | E46: =B46-$P$3 -> 325.46472 | F46: =E46-$R$3 -> 11.981822 | G46: 440 | H46: =LN(F46) -> 2.4833907 | I46: =LN(B46) -> 7.5007863
A47: 1000 | B47: 1808.9341 | C47: -7.420354 | D47: Tue Nov 23 13:42:25 2021 | E47: =B47-$P$3 -> 324.93408 | F47: =E47-$R$3 -> 11.451182 | G47: 450 | H47: =LN(F47) -> 2.438093 | I47: =LN(B47) -> 7.500493
A48: 1000 | B48: 1808.6017 | C48: -7.396544 | D48: Tue Nov 23 13:42:35 2021 | E48: =B48-$P$3 -> 324.60169 | F48: =E48-$R$3 -> 11.118785 | G48: 460 | H48: =LN(F48) -> 2.408636 | I48: =LN(B48) -> 7.5003093
A49: 1000 | B49: 1808.1422 | C49: -7.366941 | D49: Tue Nov 23 13:42:45 2021 | E49: =B49-$P$3 -> 324.14221 | F49: =E49-$R$3 -> 10.659312 | G49: 470 | H49: =LN(F49) -> 2.3664339 | I49: =LN(B49) -> 7.5000552
A50: 1000 | B50: 1807.7281 | C50: -7.341724 | D50: Tue Nov 23 13:42:55 2021 | E50: =B50-$P$3 -> 323.72815 | F50: =E50-$R$3 -> 10.245249 | G50: 480 | H50: =LN(F50) -> 2.3268141 | I50: =LN(B50) -> 7.4998262
A51: 1000 | B51: 1807.4126 | C51: -7.328966 | D51: Tue Nov 23 13:43:05 2021 | E51: =B51-$P$3 -> 323.4126 | F51: =E51-$R$3 -> 9.929698 | G51: 490 | H51: =LN(F51) -> 2.2955301 | I51: =LN(B51) -> 7.4996516
A52: 1000 | B52: 1806.74 | C52: -7.298736 | D52: Tue Nov 23 13:43:15 2021 | E52: =B52-$P$3 -> 322.73999 | F52: =E52-$R$3 -> 9.25709 | G52: 500 | H52: =LN(F52) -> 2.2253897 | I52: =LN(B52) -> 7.4992794
A53: 1000 | B53: 1806.3712 | C53: -7.288476 | D53: Tue Nov 23 13:43:25 2021 | E53: =B53-$P$3 -> 322.37122 | F53: =E53-$R$3 -> 8.888316 | G53: 510 | H53: =LN(F53) -> 2.1847376 | I53: =LN(B53) -> 7.4990753
A54: 1000 | B54: 1805.9418 | C54: -7.252112 | D54: Tue Nov 23 13:43:35 2021 | E54: =B54-$P$3 -> 321.94177 | F54: =E54-$R$3 -> 8.458872 | G54: 520 | H54: =LN(F54) -> 2.1352158 | I54: =LN(B54) -> 7.4988375
A55: 1000 | B55: 1805.52 | C55: -7.226746 | D55: Tue Nov 23 13:43:45 2021 | E55: =B55-$P$3 -> 321.52002 | F55: =E55-$R$3 -> 8.03712 | G55: 530 | H55: =LN(F55) -> 2.0840708 | I55: =LN(B55) -> 7.4986039
... A129: 1000 | B129: 1797.1434 | C129: -6.334873 | D129: Tue Nov 23 13:56:07 2021 | E129: =B129-$P$3 -> 313.14343 | F129: =E129-$R$3 -> -0.339467 | G129: 1270 | H129: =LN(F129) -> #NUM! | I129: =LN(B129) -> 7.4939537

Sheet Cu_2ndPhase
A1: Freq | B1: Magnitude | C1: Phase | D1: Time (date) | E1: Magnitude - R | F1: Bread Magnitude - Baseline | G1: Time[s] | H1: ln with baseline | I1: ln(Magnitude)
A2: 1000 | B2: 2406.2732 | C2: -23.561123 | D2: Tue Nov 23 13:57:17 2021 | E2: =B2-$P$3 -> 928.27319 | F2: =E2-$R$3 -> #VALUE! | G2: 0 | H2: =LN(F2) -> #VALUE! | I2: =LN(B2) -> 7.7858344 | L2: All values | M2: 0-1000 s | P2: Serie Resistor | R2: Baseline
A3: 1000 | B3: 2403.4275 | C3: -23.6 | D3: Tue Nov 23 13:57:28 2021 | E3: =B3-$P$3 -> 925.42749 | F3: =E3-$R$3 -> #VALUE! | G3: 10 | H3: =LN(F3) -> #VALUE! | I3: =LN(B3) -> 7.7846511 | K3: Tau: | L3: =1/(0.00007) -> 14285.714 | M3: =1/(0.0002) -> 5000 | N3: s | P3: 1478 | R3: -
A4: 1000 | B4: 2404.0728 | C4: -23.710361 | D4: Tue Nov 23 13:57:38 2021 | E4: =B4-$P$3 -> 926.07275 | F4: =E4-$R$3 -> #VALUE! | G4: 20 | H4: =LN(F4) -> #VALUE! | I4: =LN(B4) -> 7.7849196 | L4: =L3/60 -> 238.09524 | M4: =M3/60 -> 83.333333 | N4: min
A5: 1000 | B5: 2400.2234 | C5: -23.710157 | D5: Tue Nov 23 13:57:48 2021 | E5: =B5-$P$3 -> 922.22339 | F5: =E5-$R$3 -> #VALUE! | G5: 30 | H5: =LN(F5) -> #VALUE! | I5: =LN(B5) -> 7.7833171 | L5: =L4/60 -> 3.968254 | M5: =M4/60 -> 1.3888889 | N5: h
A6: 1000 | B6: 2399.5984 | C6: -23.793036 | D6: Tue Nov 23 13:57:57 2021 | E6: =B6-$P$3 -> 921.59839 | F6: =E6-$R$3 -> #VALUE! | G6: 40 | H6: =LN(F6) -> #VALUE! | I6: =LN(B6) -> 7.7830567
A7: 1000 | B7: 2399.1648 | C7: -23.838224 | D7: Tue Nov 23 13:58:08 2021 | E7: =B7-$P$3 -> 921.1648 | F7: =E7-$R$3 -> #VALUE! | G7: 50 | H7: =LN(F7) -> #VALUE! | I7: =LN(B7) -> 7.782876
A8: 1000 | B8: 2395.4502 | C8: -23.780058 | D8: Tue Nov 23 13:58:18 2021 | E8: =B8-$P$3 -> 917.45019 | F8: =E8-$R$3 -> #VALUE! | G8: 60 | H8: =LN(F8) -> #VALUE! | I8: =LN(B8) -> 7.7813265
A9: 1000 | B9: 2394.3438 | C9: -23.818539 | D9: Tue Nov 23 13:58:28 2021 | E9: =B9-$P$3 -> 916.34375 | F9: =E9-$R$3 -> #VALUE! | G9: 70 | H9: =LN(F9) -> #VALUE! | I9: =LN(B9) -> 7.7808645
A10: 1000 | B10: 2390.7698 | C10: -23.785044 | D10: Tue Nov 23 13:58:37 2021 | E10: =B10-$P$3 -> 912.76978 | F10: =E10-$R$3 -> #VALUE! | G10: 80 | H10: =LN(F10) -> #VALUE! | I10: =LN(B10) -> 7.7793707
A11: 1000 | B11: 2386.7593 | C11: -23.730198 | D11: Tue Nov 23 13:58:48 2021 | E11: =B11-$P$3 -> 908.75928 | F11: =E11-$R$3 -> #VALUE! | G11: 90 | H11: =LN(F11) -> #VALUE! | I11: =LN(B11) -> 7.7776918
A12: 1000 | B12: 2383.0522 | C12: -23.680611 | D12: Tue Nov 23 13:58:57 2021 | E12: =B12-$P$3 -> 905.05225 | F12: =E12-$R$3 -> #VALUE! | G12: 100 | H12: =LN(F12) -> #VALUE! | I12: =LN(B12) -> 7.7761374
A13: 1000 | B13: 2384.1086 | C13: -23.749008 | D13: Tue Nov 23 13:59:08 2021 | E13: =B13-$P$3 -> 906.10864 | F13: =E13-$R$3 -> #VALUE! | G13: 110 | H13: =LN(F13) -> #VALUE! | I13: =LN(B13) -> 7.7765806
A14: 1000 | B14: 2383.8606 | C14: -23.783201 | D14: Tue Nov 23 13:59:18 2021 | E14: =B14-$P$3 -> 905.8606 | F14: =E14-$R$3 -> #VALUE! | G14: 120 | H14: =LN(F14) -> #VALUE! | I14: =LN(B14) -> 7.7764766
A15: 1000 | B15: 2380.8342 | C15: -23.753965 | D15: Tue Nov 23 13:59:28 2021 | E15: =B15-$P$3 -> 902.83423 | F15: =E15-$R$3 -> #VALUE! | G15: 130 | H15: =LN(F15) -> #VALUE! | I15: =LN(B15) -> 7.7752062
A16: 1000 | B16: 2378.9348 | C16: -23.704119 | D16: Tue Nov 23 13:59:38 2021 | E16: =B16-$P$3 -> 900.93481 | F16: =E16-$R$3 -> #VALUE! | G16: 140 | H16: =LN(F16) -> #VALUE! | I16: =LN(B16) -> 7.7744081
A17: 1000 | B17: 2373.9065 | C17: -23.618757 | D17: Tue Nov 23 13:59:48 2021 | E17: =B17-$P$3 -> 895.90649 | F17: =E17-$R$3 -> #VALUE! | G17: 150 | H17: =LN(F17) -> #VALUE! | I17: =LN(B17) -> 7.7722922
... A21: 1000 | B21: 2358.8813 | C21: -23.287245 | D21: Tue Nov 23 14:00:28 2021 | E21: =B21-$P$3 -> 880.88135 | F21: =E21-$R$3 -> #VALUE! | G21: 190 | H21: =LN(F21) -> #VALUE! | I21: =LN(B21) -> 7.7659428
W22: 1000 | X22: 2118.9465 | Y22: -17.713018 | Z22: Tue Nov 23 14:00:38 2021 | AA22: =X22-$P$3 -> 640.94653 | AB22: =E22-$R$3 -> #VALUE! | AC22: 200 | AD22: =LN(AB22) -> #VALUE! | AE22: =LN(X22) -> 7.6586743
W23: 1000 | X23: 2134.3433 | Y23: -18.266033 | Z23: Tue Nov 23 14:00:48 2021 | AA23: =X23-$P$3 -> 656.34326 | AB23: =E23-$R$3 -> #VALUE! | AC23: 210 | AD23: =LN(AB23) -> #VALUE! | AE23: =LN(X23) -> 7.6659143
W24: 1000 | X24: 2134.2629 | Y24: -18.030062 | Z24: Tue Nov 23 14:00:58 2021 | AA24: =X24-$P$3 -> 656.26294 | AB24: =E24-$R$3 -> #VALUE! | AC24: 220 | AD24: =LN(AB24) -> #VALUE! | AE24: =LN(X24) -> 7.6658766
W25: 1000 | X25: 2142.8887 | Y25: -18.260897 | Z25: Tue Nov 23 14:01:08 2021 | AA25: =X25-$P$3 -> 664.88867 | AB25: =E25-$R$3 -> #VALUE! | AC25: 230 | AD25: =LN(AB25) -> #VALUE! | AE25: =LN(X25) -> 7.66991
W26: 1000 | X26: 2140.0061 | Y26: -18.145027 | Z26: Tue Nov 23 14:01:18 2021 | AA26: =X26-$P$3 -> 662.0061 | AB26: =E26-$R$3 -> #VALUE! | AC26: 240 | AD26: =LN(AB26) -> #VALUE! | AE26: =LN(X26) -> 7.668564
W27: 1000 | X27: 2140.1648 | Y27: -18.160259 | Z27: Tue Nov 23 14:01:28 2021 | AA27: =X27-$P$3 -> 662.1648 | AB27: =E27-$R$3 -> #VALUE! | AC27: 250 | AD27: =LN(AB27) -> #VALUE! | AE27: =LN(X27) -> 7.6686381
W28: 1000 | X28: 2143.9785 | Y28: -18.294228 | Z28: Tue Nov 23 14:01:38 2021 | AA28: =X28-$P$3 -> 665.97852 | AB28: =E28-$R$3 -> #VALUE! | AC28: 260 | AD28: =LN(AB28) -> #VALUE! | AE28: =LN(X28) -> 7.6704185
W29: 1000 | X29: 2144.8857 | Y29: -18.340359 | Z29: Tue Nov 23 14:01:48 2021 | AA29: =X29-$P$3 -> 666.88574 | AB29: =E29-$R$3 -> #VALUE! | AC29: 270 | AD29: =LN(AB29) -> #VALUE! | AE29: =LN(X29) -> 7.6708416
W30: 1000 | X30: 2148.5061 | Y30: -18.469599 | Z30: Tue Nov 23 14:01:58 2021 | AA30: =X30-$P$3 -> 670.5061 | AB30: =E30-$R$3 -> #VALUE! | AC30: 280 | AD30: =LN(AB30) -> #VALUE! | AE30: =LN(X30) -> 7.672528
W31: 1000 | X31: 2147.2737 | Y31: -18.441185 | Z31: Tue Nov 23 14:02:09 2021 | AA31: =X31-$P$3 -> 669.27368 | AB31: =E31-$R$3 -> #VALUE! | AC31: 290 | AD31: =LN(AB31) -> #VALUE! | AE31: =LN(X31) -> 7.6719543
W32: 1000 | X32: 2147.5149 | Y32: -18.451471 | Z32: Tue Nov 23 14:02:18 2021 | AA32: =X32-$P$3 -> 669.51489 | AB32: =E32-$R$3 -> #VALUE! | AC32: 300 | AD32: =LN(AB32) -> #VALUE! | AE32: =LN(X32) -> 7.6720666
W33: 1000 | X33: 2150.8738 | Y33: -18.590302 | Z33: Tue Nov 23 14:02:29 2021 | AA33: =X33-$P$3 -> 672.87378 | AB33: =E33-$R$3 -> #VALUE! | AC33: 310 | AD33: =LN(AB33) -> #VALUE! | AE33: =LN(X33) -> 7.6736294
... W56: 1000 | X56: 2159.1335 | Y56: -18.935732 | Z56: Tue Nov 23 14:06:19 2021 | AA56: =X56-$P$3 -> 681.13355 | AB56: =E56-$R$3 -> #VALUE! | AC56: 540 | AD56: =LN(AB56) -> #VALUE! | AE56: =LN(X56) -> 7.6774623
A57: 1000 | B57: 2160.614 | C57: -18.976099 | D57: Tue Nov 23 14:06:29 2021 | E57: =B57-$P$3 -> 682.61401 | F57: =E57-$R$3 -> #VALUE! | G57: 550 | H57: =LN(F57) -> #VALUE! | I57: =LN(B57) -> 7.6781477
A58: 1000 | B58: 2155.2363 | C58: -18.803295 | D58: Tue Nov 23 14:06:39 2021 | E58: =B58-$P$3 -> 677.23633 | F58: =E58-$R$3 -> #VALUE! | G58: 560 | H58: =LN(F58) -> #VALUE! | I58: =LN(B58) -> 7.6756557
A59: 1000 | B59: 2149.5312 | C59: -18.580439 | D59: Tue Nov 23 14:06:49 2021 | E59: =B59-$P$3 -> 671.53125 | F59: =E59-$R$3 -> #VALUE! | G59: 570 | H59: =LN(F59) -> #VALUE! | I59: =LN(B59) -> 7.6730051
A60: 1000 | B60: 2150.1843 | C60: -18.606026 | D60: Tue Nov 23 14:06:59 2021 | E60: =B60-$P$3 -> 672.18433 | F60: =E60-$R$3 -> #VALUE! | G60: 580 | H60: =LN(F60) -> #VALUE! | I60: =LN(B60) -> 7.6733089
A61: 1000 | B61: 2152.4229 | C61: -18.672333 | D61: Tue Nov 23 14:07:09 2021 | E61: =B61-$P$3 -> 674.42285 | F61: =E61-$R$3 -> #VALUE! | G61: 590 | H61: =LN(F61) -> #VALUE! | I61: =LN(B61) -> 7.6743494
A62: 1000 | B62: 2146.7351 | C62: -18.448999 | D62: Tue Nov 23 14:07:19 2021 | E62: =B62-$P$3 -> 668.73511 | F62: =E62-$R$3 -> #VALUE! | G62: 600 | H62: =LN(F62) -> #VALUE! | I62: =LN(B62) -> 7.6717034
A63: 1000 | B63: 2137.8909 | C63: -18.116478 | D63: Tue Nov 23 14:07:29 2021 | E63: =B63-$P$3 -> 659.89087 | F63: =E63-$R$3 -> #VALUE! | G63: 610 | H63: =LN(F63) -> #VALUE! | I63: =LN(B63) -> 7.667575
A64: 1000 | B64: 2133.792 | C64: -17.935532 | D64: Tue Nov 23 14:07:39 2021 | E64: =B64-$P$3 -> 655.79199 | F64: =E64-$R$3 -> #VALUE! | G64: 620 | H64: =LN(F64) -> #VALUE! | I64: =LN(B64) -> 7.665656
A65: 1000 | B65: 2128.5686 | C65: -17.689688 | D65: Tue Nov 23 14:07:49 2021 | E65: =B65-$P$3 -> 650.5686 | F65: =E65-$R$3 -> #VALUE! | G65: 630 | H65: =LN(F65) -> #VALUE! | I65: =LN(B65) -> 7.663205
...

Sheet PANI_2ndPhase
A1: Freq | B1: Magnitude | C1: Phase | D1: Time (date) | E1: Magnitude - R | F1: Bread Magnitude - Baseline | G1: Time[s] | H1: ln with baseline | I1: ln(Magnitude)
A2: 1000 | B2: 2368.3127 | C2: -12.869069 | D2: Tue Nov 23 13:56:17 2021 | E2: =B2-$P$3 -> 884.31274 | F2: =E2-$R$3 -> 432.77584 | G2: 0 | H2: =LN(F2) -> 6.0702199 | I2: =LN(B2) -> 7.7699331 | L2: All values | M2: 0-500 s | P2: Serie Resistor | R2: Baseline
A3: 1000 | B3: 2283.4917 | C3: -16.458771 | D3: Tue Nov 23 13:56:27 2021 | E3: =B3-$P$3 -> 799.4917 | F3: =E3-$R$3 -> 347.9548 | G3: 10 | H3: =LN(F3) -> 5.8520726 | I3: =LN(B3) -> 7.733461 | K3: Tau: | L3: =1/(0.00003) -> 33333.333 | M3: =1/(0.00008) -> 12500 | N3: s | P3: 1484 | R3: 451.5369
A4: 1000 | B4: 2182.5806 | C4: -15.14079 | D4: Tue Nov 23 13:56:37 2021 | E4: =B4-$P$3 -> 698.58057 | F4: =E4-$R$3 -> 247.04367 | G4: 20 | H4: =LN(F4) -> 5.5095651 | I4: =LN(B4) -> 7.6882632 | L4: =L3/60 -> 555.55556 | M4: =M3/60 -> 208.33333 | N4: min
A5: 1000 | B5: 2138.2336 | C5: -14.740842 | D5: Tue Nov 23 13:56:47 2021 | E5: =B5-$P$3 -> 654.23364 | F5: =E5-$R$3 -> 202.69674 | G5: 30 | H5: =LN(F5) -> 5.311711 | I5: =LN(B5) -> 7.6677354 | L5: =L4/60 -> 9.2592593 | M5: =M4/60 -> 3.4722222 | N5: h
A6: 1000 | B6: 2112.7607 | C6: -14.35301 | D6: Tue Nov 23 13:56:57 2021 | E6: =B6-$P$3 -> 628.76074 | F6: =E6-$R$3 -> 177.22384 | G6: 40 | H6: =LN(F6) -> 5.1774136 | I6: =LN(B6) -> 7.6557508
A7: 1000 | B7: 2094.376 | C7: -14.039176 | D7: Tue Nov 23 13:57:07 2021 | E7: =B7-$P$3 -> 610.37598 | F7: =E7-$R$3 -> 158.83908 | G7: 50 | H7: =LN(F7) -> 5.0678916 | I7: =LN(B7) -> 7.6470109
A8: 1000 | B8: 2079.8213 | C8: -13.76366 | D8: Tue Nov 23 13:57:17 2021 | E8: =B8-$P$3 -> 595.82129 | F8: =E8-$R$3 -> 144.28439 | G8: 60 | H8: =LN(F8) -> 4.9717863 | I8: =LN(B8) -> 7.6400373
A9: 1000 | B9: 2066.7615 | C9: -13.510261 | D9: Tue Nov 23 13:57:27 2021 | E9: =B9-$P$3 -> 582.76147 | F9: =E9-$R$3 -> 131.22457 | G9: 70 | H9: =LN(F9) -> 4.8769102 | I9: =LN(B9) -> 7.6337382
A10: 1000 | B10: 2056.6333 | C10: -13.315831 | D10: Tue Nov 23 13:57:37 2021 | E10: =B10-$P$3 -> 572.6333 | F10: =E10-$R$3 -> 121.0964 | G10: 80 | H10: =LN(F10) -> 4.7965869 | I10: =LN(B10) -> 7.6288256
A11: 1000 | B11: 2047.8258 | C11: -13.126608 | D11: Tue Nov 23 13:57:47 2021 | E11: =B11-$P$3 -> 563.82581 | F11: =E11-$R$3 -> 112.28891 | G11: 90 | H11: =LN(F11) -> 4.7210751 | I11: =LN(B11) -> 7.6245339
A12: 1000 | B12: 2042.4565 | C12: -13.014812 | D12: Tue Nov 23 13:57:57 2021 | E12: =B12-$P$3 -> 558.45654 | F12: =E12-$R$3 -> 106.91964 | G12: 100 | H12: =LN(F12) -> 4.6720776 | I12: =LN(B12) -> 7.6219086
A13: 1000 | B13: 2036.2487 | C13: -12.861078 | D13: Tue Nov 23 13:58:07 2021 | E13: =B13-$P$3 -> 552.24866 | F13: =E13-$R$3 -> 100.71176 | G13: 110 | H13: =LN(F13) -> 4.6122625 | I13: =LN(B13) -> 7.6188645
A14: 1000 | B14: 2029.5493 | C14: -12.713669 | D14: Tue Nov 23 13:58:17 2021 | E14: =B14-$P$3 -> 545.54932 | F14: =E14-$R$3 -> 94.012416 | G14: 120 | H14: =LN(F14) -> 4.5434269 | I14: =LN(B14) -> 7.615569
A15: 1000 | B15: 2024.7068 | C15: -12.589072 | D15: Tue Nov 23 13:58:28 2021 | E15: =B15-$P$3 -> 540.70679 | F15: =E15-$R$3 -> 89.169887 | G15: 130 | H15: =LN(F15) -> 4.4905434 | I15: =LN(B15) -> 7.6131802
A16: 1000 | B16: 2019.8066 | C16: -12.485691 | D16: Tue Nov 23 13:58:37 2021 | E16: =B16-$P$3 -> 535.80664 | F16: =E16-$R$3 -> 84.269741 | G16: 140 | H16: =LN(F16) -> 4.4340229 | I16: =LN(B16) -> 7.6107571
A17: 1000 | B17: 2015.9656 | C17: -12.366559 | D17: Tue Nov 23 13:58:47 2021 | E17: =B17-$P$3 -> 531.96558 | F17: =E17-$R$3 -> 80.428676 | G17: 150 | H17: =LN(F17) -> 4.3873708 | I17: =LN(B17) -> 7.6088536
... A39: 1000 | B39: 1967.191 | C39: -10.987584 | D39: Tue Nov 23 14:02:28 2021 | E39: =B39-$P$3 -> 483.19104 | F39: =E39-$R$3 -> 31.65414 | G39: 370 | H39: =LN(F39) -> 3.4548689 | I39: =LN(B39) -> 7.5843619
A40: 1000 | B40: 1965.8971 | C40: -10.948256 | D40: Tue Nov 23 14:02:37 2021 | E40: =B40-$P$3 -> 481.8971 | F40: =E40-$R$3 -> 30.360195 | G40: 380 | H40: =LN(F40) -> 3.4131324 | I40: =LN(B40) -> 7.583704 | T40: -0.0056
A41: 1000 | B41: 1964.5135 | C41: -10.890036 | D41: Tue Nov 23 14:02:48 2021 | E41: =B41-$P$3 -> 480.51355 | F41: =E41-$R$3 -> 28.97665 | G41: 390 | H41: =LN(F41) -> 3.3664903 | I41: =LN(B41) -> 7.5829999 | S41: Tau: | T41: =1/ABS(T40) -> 178.57143 | U41: s
A42: 1000 | B42: 1963.395 | C42: -10.837908 | D42: Tue Nov 23 14:02:58 2021 | E42: =B42-$P$3 -> 479.39502 | F42: =E42-$R$3 -> 27.85812 | G42: 400 | H42: =LN(F42) -> 3.3271245 | I42: =LN(B42) -> 7.5824304 | T42: =T41/60 -> 2.9761905 | U42: min
A43: 1000 | B43: 1961.989 | C43: -10.807404 | D43: Tue Nov 23 14:03:08 2021 | E43: =B43-$P$3 -> 477.98901 | F43: =E43-$R$3 -> 26.452114 | G43: 410 | H43: =LN(F43) -> 3.2753361 | I43: =LN(B43) -> 7.581714 | T43: =T42/60 -> 0.049603175 | U43: h
A44: 1000 | B44: 1961.0656 | C44: -10.757789 | D44: Tue Nov 23 14:03:18 2021 | E44: =B44-$P$3 -> 477.06555 | F44: =E44-$R$3 -> 25.528652 | G44: 420 | H44: =LN(F44) -> 3.2398014 | I44: =LN(B44) -> 7.5812433
A45: 1000 | B45: 1959.8041 | C45: -10.73488 | D45: Tue Nov 23 14:03:28 2021 | E45: =B45-$P$3 -> 475.80408 | F45: =E45-$R$3 -> 24.267177 | G45: 430 | H45: =LN(F45) -> 3.1891247 | I45: =LN(B45) -> 7.5805998
A46: 1000 | B46: 1958.454 | C46: -10.683094 | D46: Tue Nov 23 14:03:37 2021 | E46: =B46-$P$3 -> 474.45398 | F46: =E46-$R$3 -> 22.917079 | G46: 440 | H46: =LN(F46) -> 3.1318824 | I46: =LN(B46) -> 7.5799107
A47: 1000 | B47: 1957.6989 | C47: -10.675171 | D47: Tue Nov 23 14:03:48 2021 | E47: =B47-$P$3 -> 473.69885 | F47: =E47-$R$3 -> 22.161953 | G47: 450 | H47: =LN(F47) -> 3.098377 | I47: =LN(B47) -> 7.579525
A48: 1000 | B48: 1957.7051 | C48: -10.644067 | D48: Tue Nov 23 14:03:58 2021 | E48: =B48-$P$3 -> 473.70508 | F48: =E48-$R$3 -> 22.168178 | G48: 460 | H48: =LN(F48) -> 3.0986578 | I48: =LN(B48) -> 7.5795282
A49: 1000 | B49: 1956.3696 | C49: -10.603564 | D49: Tue Nov 23 14:04:08 2021 | E49: =B49-$P$3 -> 472.36963 | F49: =E49-$R$3 -> 20.832729 | G49: 470 | H49: =LN(F49) -> 3.0365253 | I49: =LN(B49) -> 7.5788458
A50: 1000 | B50: 1955.3488 | C50: -10.585449 | D50: Tue Nov 23 14:04:18 2021 | E50: =B50-$P$3 -> 471.34875 | F50: =E50-$R$3 -> 19.811855 | G50: 480 | H50: =LN(F50) -> 2.9862805 | I50: =LN(B50) -> 7.5783238
A51: 1000 | B51: 1954.5033 | C51: -10.558744 | D51: Tue Nov 23 14:04:28 2021 | E51: =B51-$P$3 -> 470.5033 | F51: =E51-$R$3 -> 18.966396 | G51: 490 | H51: =LN(F51) -> 2.9426688 | I51: =LN(B51) -> 7.5778914
A52: 1000 | B52: 1954.2167 | C52: -10.535098 | D52: Tue Nov 23 14:04:38 2021 | E52: =B52-$P$3 -> 470.21667 | F52: =E52-$R$3 -> 18.679775 | G52: 500 | H52: =LN(F52) -> 2.9274414 | I52: =LN(B52) -> 7.5777447
A53: 1000 | B53: 1953.059 | C53: -10.495879 | D53: Tue Nov 23 14:04:48 2021 | E53: =B53-$P$3 -> 469.05896 | F53: =E53-$R$3 -> 17.52206 | G53: 510 | H53: =LN(F53) -> 2.8634607 | I53: =LN(B53) -> 7.5771521
A54: 1000 | B54: 1951.7324 | C54: -10.457916 | D54: Tue Nov 23 14:04:58 2021 | E54: =B54-$P$3 -> 467.73242 | F54: =E54-$R$3 -> 16.195522 | G54: 520 | H54: =LN(F54) -> 2.7847348 | I54: =LN(B54) -> 7.5764727
A55: 1000 | B55: 1951.2035 | C55: -10.429585 | D55: Tue Nov 23 14:05:08 2021 | E55: =B55-$P$3 -> 467.20349 | F55: =E55-$R$3 -> 15.666591 | G55: 530 | H55: =LN(F55) -> 2.7515305 | I55: =LN(B55) -> 7.5762016
... A191: 1000 | B191: 1930.8052 | C191: -8.10228 | D191: Tue Nov 23 14:27:51 2021 | E191: =B191-$P$3 -> 446.80518 | F191: =E191-$R$3 -> -4.731724 | G191: 1890 | H191: =LN(F191) -> #NUM! | I191: =LN(B191) -> 7.5656924

Sheet Cu_3rdPhase
A1: Freq | B1: Magnitude | C1: Phase | D1: Time (date) | E1: Magnitude - R | F1: Bread Magnitude - Baseline | G1: Time[s] | H1: ln with baseline | I1: ln(Magnitude)
A2: 1000 | B2: 5058.9858 | C2: -24.491081 | D2: Tue Nov 23 14:28:42 2021 | E2: =B2-$P$3 -> 3580.9858 | F2: =E2-$R$3 -> 2210.9858 | G2: 0 | H2: =LN(F2) -> 7.7011938 | I2: =LN(B2) -> 8.5289213 | L2: All values | P2: Serie Resistor | R2: Baseline
A3: 1000 | B3: 4750.5229 | C3: -24.7512 | D3: Tue Nov 23 14:28:52 2021 | E3: =B3-$P$3 -> 3272.5229 | F3: =E3-$R$3 -> 1902.5229 | G3: 10 | H3: =LN(F3) -> 7.5509362 | I3: =LN(B3) -> 8.46601 | K3: Tau: | L3: =1/(0.001) -> 1000 | M3: s | P3: 1478 | R3: 1370
A4: 1000 | B4: 4098.8296 | C4: -23.593197 | D4: Tue Nov 23 14:29:02 2021 | E4: =B4-$P$3 -> 2620.8296 | F4: =E4-$R$3 -> 1250.8296 | G4: 20 | H4: =LN(F4) -> 7.1315623 | I4: =LN(B4) -> 8.3184567 | L4: =L3/60 -> 16.666667 | M4: min
A5: 1000 | B5: 4050.9204 | C5: -24.515327 | D5: Tue Nov 23 14:29:13 2021 | E5: =B5-$P$3 -> 2572.9204 | F5: =E5-$R$3 -> 1202.9204 | G5: 30 | H5: =LN(F5) -> 7.0925076 | I5: =LN(B5) -> 8.3066994 | L5: =L4/60 -> 0.27777778 | M5: h
A6: 1000 | B6: 3968.2373 | C6: -25.006445 | D6: Tue Nov 23 14:29:22 2021 | E6: =B6-$P$3 -> 2490.2373 | F6: =E6-$R$3 -> 1120.2373 | G6: 40 | H6: =LN(F6) -> 7.0212958 | I6: =LN(B6) -> 8.2860773
A7: 1000 | B7: 3872.1646 | C7: -25.273151 | D7: Tue Nov 23 14:29:33 2021 | E7: =B7-$P$3 -> 2394.1646 | F7: =E7-$R$3 -> 1024.1646 | G7: 50 | H7: =LN(F7) -> 6.9316325 | I7: =LN(B7) -> 8.2615689
A8: 1000 | B8: 3787.4688 | C8: -25.459436 | D8: Tue Nov 23 14:29:42 2021 | E8: =B8-$P$3 -> 2309.4688 | F8: =E8-$R$3 -> 939.46875 | G8: 60 | H8: =LN(F8) -> 6.8453146 | I8: =LN(B8) -> 8.2394532
A9: 1000 | B9: 3713.4373 | C9: -25.664192 | D9: Tue Nov 23 14:29:53 2021 | E9: =B9-$P$3 -> 2235.4373 | F9: =E9-$R$3 -> 865.43726 | G9: 70 | H9: =LN(F9) -> 6.7632349 | I9: =LN(B9) -> 8.2197132
A10: 1000 | B10: 3647.6431 | C10: -25.761496 | D10: Tue Nov 23 14:30:02 2021 | E10: =B10-$P$3 -> 2169.6431 | F10: =E10-$R$3 -> 799.64307 | G10: 80 | H10: =LN(F10) -> 6.6841655 | I10: =LN(B10) -> 8.2018365
A11: 1000 | B11: 3579.4934 | C11: -25.794773 | D11: Tue Nov 23 14:30:12 2021 | E11: =B11-$P$3 -> 2101.4934 | F11: =E11-$R$3 -> 731.49341 | G11: 90 | H11: =LN(F11) -> 6.5950882 | I11: =LN(B11) -> 8.1829766
A12: 1000 | B12: 3522.283 | C12: -25.855698 | D12: Tue Nov 23 14:30:22 2021 | E12: =B12-$P$3 -> 2044.283 | F12: =E12-$R$3 -> 674.28296 | G12: 100 | H12: =LN(F12) -> 6.5136498 | I12: =LN(B12) -> 8.1668646
A13: 1000 | B13: 3453.3159 | C13: -25.680382 | D13: Tue Nov 23 14:30:32 2021 | E13: =B13-$P$3 -> 1975.3159 | F13: =E13-$R$3 -> 605.31592 | G13: 110 | H13: =LN(F13) -> 6.4057505 | I13: =LN(B13) -> 8.1470902
A14: 1000 | B14: 3384.0903 | C14: -25.410124 | D14: Tue Nov 23 14:30:43 2021 | E14: =B14-$P$3 -> 1906.0903 | F14: =E14-$R$3 -> 536.09033 | G14: 120 | H14: =LN(F14) -> 6.2843027 | I14: =LN(B14) -> 8.1268404
A15: 1000 | B15: 3352.8103 | C15: -25.651447 | D15: Tue Nov 23 14:30:53 2021 | E15: =B15-$P$3 -> 1874.8103 | F15: =E15-$R$3 -> 504.8103 | G15: 130 | H15: =LN(F15) -> 6.2241827 | I15: =LN(B15) -> 8.1175542
A16: 1000 | B16: 3322.8037 | C16: -25.806288 | D16: Tue Nov 23 14:31:02 2021 | E16: =B16-$P$3 -> 1844.8037 | F16: =E16-$R$3 -> 474.80371 | G16: 140 | H16: =LN(F16) -> 6.1629015 | I16: =LN(B16) -> 8.1085642
A17: 1000 | B17: 3288.6042 | C17: -25.848198 | D17: Tue Nov 23 14:31:12 2021 | E17: =B17-$P$3 -> 1810.6042 | F17: =E17-$R$3 -> 440.60425 | G17: 150 | H17: =LN(F17) -> 6.0881471 | I17: =LN(B17) -> 8.0982185
... A38: 1000 | B38: 2832.8508 | C38: -24.88883 | D38: Tue Nov 23 14:34:43 2021 | E38: =B38-$P$3 -> 1354.8508 | F38: =E38-$R$3 -> -15.14917 | G38: 360 | H38: =LN(F38) -> #NUM! | I38: =LN(B38) -> 7.9490388
A39: 1000 | B39: 2820.7786 | C39: -24.810364 | D39: Tue Nov 23 14:34:52 2021 | E39: =B39-$P$3 -> 1342.7786 | F39: =E39-$R$3 -> -27.221436 | G39: 370 | H39: =LN(F39) -> #NUM! | I39: =LN(B39) -> 7.9447682 | S39: -0.0129
A40: 1000 | B40: 2815.4839 | C40: -24.867315 | D40: Tue Nov 23 14:35:03 2021 | E40: =B40-$P$3 -> 1337.4839 | F40: =E40-$R$3 -> -32.516113 | G40: 380 | H40: =LN(F40) -> #NUM! | I40: =LN(B40) -> 7.9428894 | R40: Tau: | S40: =1/ABS(S39) -> 77.51938 | T40: s
A41: 1000 | B41: 2803.6499 | C41: -24.787264 | D41: Tue Nov 23 14:35:13 2021 | E41: =B41-$P$3 -> 1325.6499 | F41: =E41-$R$3 -> -44.350098 | G41: 390 | H41: =LN(F41) -> #NUM! | I41: =LN(B41) -> 7.9386774 | S41: =S40/60 -> 1.2919897 | T41: min
A42: 1000 | B42: 2798.2314 | C42: -24.845869 | D42: Tue Nov 23 14:35:23 2021 | E42: =B42-$P$3 -> 1320.2314 | F42: =E42-$R$3 -> -49.768555 | G42: 400 | H42: =LN(F42) -> #NUM! | I42: =LN(B42) -> 7.9367429 | S42: =S41/60 -> 0.021533161 | T42: h
A43: 1000 | B43: 2784.4172 | C43: -24.735641 | D43: Tue Nov 23 14:35:33 2021 | E43: =B43-$P$3 -> 1306.4172 | F43: =E43-$R$3 -> -63.582764 | G43: 410 | H43: =LN(F43) -> #NUM! | I43: =LN(B43) -> 7.9317939
A44: 1000 | B44: 2778.5435 | C44: -24.749193 | D44: Tue Nov 23 14:35:43 2021 | E44: =B44-$P$3 -> 1300.5435 | F44: =E44-$R$3 -> -69.456543 | G44: 420 | H44: =LN(F44) -> #NUM! | I44: =LN(B44) -> 7.9296821
A45: 1000 | B45: 2773.0164 | C45: -24.732979 | D45: Tue Nov 23 14:35:53 2021 | E45: =B45-$P$3 -> 1295.0164 | F45: =E45-$R$3 -> -74.983643 | G45: 430 | H45: =LN(F45) -> #NUM! | I45: =LN(B45) -> 7.9276909
A46: 1000 | B46: 2766.2705 | C46: -24.708622 | D46: Tue Nov 23 14:36:03 2021 | E46: =B46-$P$3 -> 1288.2705 | F46: =E46-$R$3 -> -81.729492 | G46: 440 | H46: =LN(F46) -> #NUM! | I46: =LN(B46) -> 7.9252553
A47: 1000 | B47: 2761.3999 | C47: -24.741503 | D47: Tue Nov 23 14:36:13 2021 | E47: =B47-$P$3 -> 1283.3999 | F47: =E47-$R$3 -> -86.600098 | G47: 450 | H47: =LN(F47) -> #NUM! | I47: =LN(B47) -> 7.923493
A48: 1000 | B48: 2756.2915 | C48: -24.750137 | D48: Tue Nov 23 14:36:24 2021 | E48: =B48-$P$3 -> 1278.2915 | F48: =E48-$R$3 -> -91.708496 | G48: 460 | H48: =LN(F48) -> #NUM! | I48: =LN(B48) -> 7.9216414

Sheet PANI_3rdPhase
A1: Freq | B1: Magnitude | C1: Phase | D1: Time (date) | E1: Magnitude - R | F1: Bread Magnitude - Baseline | G1: Time[s] | H1: ln with baseline | I1: ln(Magnitude)
A2: 1000 | B2: 3181.7458 | C2: -19.739941 | D2: Tue Nov 23 14:28:21 2021 | E2: =B2-$P$3 -> 1697.7458 | F2: =E2-$R$3 -> 1066.1977 | G2: 0 | H2: =LN(F2) -> 6.9718541 | I2: =LN(B2) -> 8.0651853 | L2: All values | P2: Serie Resistor | R2: Baseline
A3: 1000 | B3: 2859.4561 | C3: -18.098795 | D3: Tue Nov 23 14:28:32 2021 | E3: =B3-$P$3 -> 1375.4561 | F3: =E3-$R$3 -> 743.90796 | G3: 10 | H3: =LN(F3) -> 6.6119173 | I3: =LN(B3) -> 7.9583867 | K3: Tau: | L3: =1/(0.0005) -> 2000 | M3: s | P3: 1484 | R3: 631.5481
A4: 1000 | B4: 2684.6038 | C4: -17.186363 | D4: Tue Nov 23 14:28:42 2021 | E4: =B4-$P$3 -> 1200.6038 | F4: =E4-$R$3 -> 569.05566 | G4: 20 | H4: =LN(F4) -> 6.3439783 | I4: =LN(B4) -> 7.8952884 | L4: =L3/60 -> 33.333333 | M4: min
A5: 1000 | B5: 2572.4673 | C5: -16.526745 | D5: Tue Nov 23 14:28:51 2021 | E5: =B5-$P$3 -> 1088.4673 | F5: =E5-$R$3 -> 456.91919 | G5: 30 | H5: =LN(F5) -> 6.1245065 | I5: =LN(B5) -> 7.8526208 | L5: =L4/60 -> 0.55555556 | M5: h
A6: 1000 | B6: 2477.9021 | C6: -15.797336 | D6: Tue Nov 23 14:29:02 2021 | E6: =B6-$P$3 -> 993.9021 | F6: =E6-$R$3 -> 362.354 | G6: 40 | H6: =LN(F6) -> 5.8926216 | I6: =LN(B6) -> 7.8151676
A7: 1000 | B7: 2416.3301 | C7: -15.319304 | D7: Tue Nov 23 14:29:11 2021 | E7: =B7-$P$3 -> 932.33008 | F7: =E7-$R$3 -> 300.78198 | G7: 50 | H7: =LN(F7) -> 5.7063857 | I7: =LN(B7) -> 7.7900052
A8: 1000 | B8: 2367.0034 | C8: -14.943193 | D8: Tue Nov 23 14:29:22 2021 | E8: =B8-$P$3 -> 883.00342 | F8: =E8-$R$3 -> 251.45532 | G8: 60 | H8: =LN(F8) -> 5.5272653 | I8: =LN(B8) -> 7.7693801
A9: 1000 | B9: 2335.6006 | C9: -14.792081 | D9: Tue Nov 23 14:29:31 2021 | E9: =B9-$P$3 -> 851.60059 | F9: =E9-$R$3 -> 220.05249 | G9: 70 | H9: =LN(F9) -> 5.3938661 | I9: =LN(B9) -> 7.7560243
A10: 1000 | B10: 2304.0879 | C10: -14.562164 | D10: Tue Nov 23 14:29:41 2021 | E10: =B10-$P$3 -> 820.08789 | F10: =E10-$R$3 -> 188.53979 | G10: 80 | H10: =LN(F10) -> 5.2393091 | I10: =LN(B10) -> 7.7424402
A11: 1000 | B11: 2281.3047 | C11: -14.389893 | D11: Tue Nov 23 14:29:52 2021 | E11: =B11-$P$3 -> 797.30469 | F11: =E11-$R$3 -> 165.75659 | G11: 90 | H11: =LN(F11) -> 5.1105204 | I11: =LN(B11) -> 7.7325028
A12: 1000 | B12: 2258.7029 | C12: -14.155398 | D12: Tue Nov 23 14:30:02 2021 | E12: =B12-$P$3 -> 774.70288 | F12: =E12-$R$3 -> 143.15478 | G12: 100 | H12: =LN(F12) -> 4.9639264 | I12: =LN(B12) -> 7.722546
A13: 1000 | B13: 2238.8279 | C13: -13.936832 | D13: Tue Nov 23 14:30:11 2021 | E13: =B13-$P$3 -> 754.82788 | F13: =E13-$R$3 -> 123.27978 | G13: 110 | H13: =LN(F13) -> 4.8144564 | I13: =LN(B13) -> 7.7137077
A14: 1000 | B14: 2222.8171 | C14: -13.796637 | D14: Tue Nov 23 14:30:22 2021 | E14: =B14-$P$3 -> 738.81714 | F14: =E14-$R$3 -> 107.26904 | G14: 120 | H14: =LN(F14) -> 4.6753401 | I14: =LN(B14) -> 7.7065307
A15: 1000 | B15: 2209.9062 | C15: -13.672668 | D15: Tue Nov 23 14:30:31 2021 | E15: =B15-$P$3 -> 725.90625 | F15: =E15-$R$3 -> 94.35815 | G15: 130 | H15: =LN(F15) -> 4.5470976 | I15: =LN(B15) -> 7.7007054
A16: 1000 | B16: 2198.3591 | C16: -13.547348 | D16: Tue Nov 23 14:30:42 2021 | E16: =B16-$P$3 -> 714.35913 | F16: =E16-$R$3 -> 82.811031 | G16: 140 | H16: =LN(F16) -> 4.4165613 | I16: =LN(B16) -> 7.6954665
A17: 1000 | B17: 2185.636 | C17: -13.369762 | D17: Tue Nov 23 14:30:52 2021 | E17: =B17-$P$3 -> 701.63599 | F17: =E17-$R$3 -> 70.087886 | G17: 150 | H17: =LN(F17) -> 4.24975 | I17: =LN(B17) -> 7.6896621
... A38: 1000 | B38: 2074.5149 | C38: -11.483524 | D38: Tue Nov 23 14:34:23 2021 | E38: =B38-$P$3 -> 590.51489 | F38: =E38-$R$3 -> -41.033207 | G38: 360 | H38: =LN(F38) -> #NUM! | I38: =LN(B38) -> 7.6374826
A39: 1000 | B39: 2072.1138 | C39: -11.428037 | D39: Tue Nov 23 14:34:32 2021 | E39: =B39-$P$3 -> 588.11377 | F39: =E39-$R$3 -> -43.43433 | G39: 370 | H39: =LN(F39) -> #NUM! | I39: =LN(B39) -> 7.6363245 | T39: -0.0191
A40: 1000 | B40: 2069.8279 | C40: -11.377369 | D40: Tue Nov 23 14:34:42 2021 | E40: =B40-$P$3 -> 585.82788 | F40: =E40-$R$3 -> -45.720219 | G40: 380 | H40: =LN(F40) -> #NUM! | I40: =LN(B40) -> 7.6352207 | S40: Tau: | T40: =1/ABS(T39) -> 52.356021 | U40: s
A41: 1000 | B41: 2067.8625 | C41: -11.311062 | D41: Tue Nov 23 14:34:52 2021 | E41: =B41-$P$3 -> 583.86255 | F41: =E41-$R$3 -> -47.685551 | G41: 390 | H41: =LN(F41) -> #NUM! | I41: =LN(B41) -> 7.6342708 | T41: =T40/60 -> 0.87260035 | U41: min
A42: 1000 | B42: 2065.2273 | C42: -11.263238 | D42: Tue Nov 23 14:35:02 2021 | E42: =B42-$P$3 -> 581.2273 | F42: =E42-$R$3 -> -50.320805 | G42: 400 | H42: =LN(F42) -> #NUM! | I42: =LN(B42) -> 7.6329956 | T42: =T41/60 -> 0.014543339 | U42: h
A43: 1000 | B43: 2062.9507 | C43: -11.18708 | D43: Tue Nov 23 14:35:12 2021 | E43: =B43-$P$3 -> 578.95068 | F43: =E43-$R$3 -> -52.597416 | G43: 410 | H43: =LN(F43) -> #NUM! | I43: =LN(B43) -> 7.6318926
A44: 1000 | B44: 2060.8481 | C44: -11.157697 | D44: Tue Nov 23 14:35:22 2021 | E44: =B44-$P$3 -> 576.84814 | F44: =E44-$R$3 -> -54.699955 | G44: 420 | H44: =LN(F44) -> #NUM! | I44: =LN(B44) -> 7.6308729
A45: 1000 | B45: 2060.259 | C45: -11.141919 | D45: Tue Nov 23 14:35:32 2021 | E45: =B45-$P$3 -> 576.25903 | F45: =E45-$R$3 -> -55.289067 | G45: 430 | H45: =LN(F45) -> #NUM! | I45: =LN(B45) -> 7.630587
A46: 1000 | B46: 2057.8972 | C46: -11.074805 | D46: Tue Nov 23 14:35:42 2021 | E46: =B46-$P$3 -> 573.89722 | F46: =E46-$R$3 -> -57.650883 | G46: 440 | H46: =LN(F46) -> #NUM! | I46: =LN(B46) -> 7.62944
A47: 1000 | B47: 2055.8618 | C47: -11.011039 | D47: Tue Nov 23 14:35:52 2021 | E47: =B47-$P$3 -> 571.86182 | F47: =E47-$R$3 -> -59.686284 | G47: 450 | H47: =LN(F47) -> #NUM! | I47: =LN(B47) -> 7.6284504
A48: 1000 | B48: 2054.7466 | C48: -10.950538 | D48: Tue Nov 23 14:36:02 2021 | E48: =B48-$P$3 -> 570.74658 | F48: =E48-$R$3 -> -60.801518 | G48: 460 | H48: =LN(F48) -> #NUM! | I48: =LN(B48) -> 7.6279078
A49: 1000 | B49: 2052.9773 | C49: -10.899078 | D49: Tue Nov 23 14:36:13 2021 | E49: =B49-$P$3 -> 568.9773 | F49: =E49-$R$3 -> -62.570805 | G49: 470 | H49: =LN(F49) -> #NUM! | I49: =LN(B49) -> 7.6270464
A50: 1000 | B50: 2051.5068 | C50: -10.860147 | D50: Tue Nov 23 14:36:22 2021 | E50: =B50-$P$3 -> 567.50684 | F50: =E50-$R$3 -> -64.041264 | G50: 480 | H50: =LN(F50) -> #NUM! | I50: =LN(B50) -> 7.6263298

Sheet Summary
A1: Summary
B2: Cu_1stPhase | C2: PANI_1stPhase | D2: Cu_2ndPhase | E2: PANI_2ndPhase | F2: Cu_3rdPhase | G2: PANI_3rdPhase
A3: Slope | B3: - | C3: =PANI_1stPhase!T40 -> -0.006 | D3: - | E3: =PANI_2ndPhase!T40 -> -0.0056 | F3: =Cu_3rdPhase!S39 -> -0.0129 | G3: =PANI_3rdPhase!T39 -> -0.0191
A4: Tau | B4: - | C4: =PANI_1stPhase!T41 -> 166.66667 | D4: - | E4: =PANI_2ndPhase!T41 -> 178.57143 | F4: =Cu_3rdPhase!S40 -> 77.51938 | G4: =PANI_3rdPhase!T40 -> 52.356021 | H4: s
